number of tasks = 
output ['/veracruz/projects/c/cquant/Dirac-Quantum-Walk/QuantumWalk/main.py', '8', '500', '1', '2', '1', '2', '10000', 'aer_simulator_statevector', '388422', '10']
output ['/veracruz/projects/c/cquant/Dirac-Quantum-Walk/QuantumWalk/main.py', '8', '500', '1', '2', '1', '2', '10000', 'aer_simulator_statevector', '388422', '10']
output ['/veracruz/projects/c/cquant/Dirac-Quantum-Walk/QuantumWalk/main.py', '8', '500', '1', '2', '1', '2', '10000', 'aer_simulator_statevector', '388422', '10']
Traceback (most recent call last):
  File "/veracruz/projects/c/cquant/Dirac-Quantum-Walk/QuantumWalk/main.py", line 38, in <module>
    exec_answers = execute_circuits(all_results,shots,simulator,num_threads)
  File "/veracruz/projects/c/cquant/Dirac-Quantum-Walk/QuantumWalk/execute_circuits.py", line 9, in execute_circuits
    circuits_list = transpile(circuits_list, sim_statevector)
  File "/veracruz/home/d/dgoncalves/.local/lib/python3.8/site-packages/qiskit/compiler/transpiler.py", line 372, in transpile
    circuits = parallel.parallel_map(
  File "/veracruz/home/d/dgoncalves/.local/lib/python3.8/site-packages/qiskit/tools/parallel.py", line 187, in parallel_map
    raise error
  File "/veracruz/home/d/dgoncalves/.local/lib/python3.8/site-packages/qiskit/tools/parallel.py", line 175, in parallel_map
    future = executor.map(_task_wrapper, param)
  File "/apps/software/Anaconda/2020.11/lib/python3.8/concurrent/futures/process.py", line 674, in map
    results = super().map(partial(_process_chunk, fn),
  File "/apps/software/Anaconda/2020.11/lib/python3.8/concurrent/futures/_base.py", line 600, in map
    fs = [self.submit(fn, *args) for args in zip(*iterables)]
  File "/apps/software/Anaconda/2020.11/lib/python3.8/concurrent/futures/_base.py", line 600, in <listcomp>
    fs = [self.submit(fn, *args) for args in zip(*iterables)]
  File "/apps/software/Anaconda/2020.11/lib/python3.8/concurrent/futures/process.py", line 645, in submit
    self._start_queue_management_thread()
  File "/apps/software/Anaconda/2020.11/lib/python3.8/concurrent/futures/process.py", line 584, in _start_queue_management_thread
    self._adjust_process_count()
  File "/apps/software/Anaconda/2020.11/lib/python3.8/concurrent/futures/process.py", line 608, in _adjust_process_count
    p.start()
  File "/apps/software/Anaconda/2020.11/lib/python3.8/multiprocessing/process.py", line 121, in start
    self._popen = self._Popen(self)
  File "/apps/software/Anaconda/2020.11/lib/python3.8/multiprocessing/context.py", line 277, in _Popen
    return Popen(process_obj)
  File "/apps/software/Anaconda/2020.11/lib/python3.8/multiprocessing/popen_fork.py", line 19, in __init__
    self._launch(process_obj)
  File "/apps/software/Anaconda/2020.11/lib/python3.8/multiprocessing/popen_fork.py", line 70, in _launch
    self.pid = os.fork()
OSError: [Errno 12] Cannot allocate memory
Traceback (most recent call last):
  File "/veracruz/projects/c/cquant/Dirac-Quantum-Walk/QuantumWalk/main.py", line 38, in <module>
    exec_answers = execute_circuits(all_results,shots,simulator,num_threads)
  File "/veracruz/projects/c/cquant/Dirac-Quantum-Walk/QuantumWalk/execute_circuits.py", line 9, in execute_circuits
    circuits_list = transpile(circuits_list, sim_statevector)
  File "/veracruz/home/d/dgoncalves/.local/lib/python3.8/site-packages/qiskit/compiler/transpiler.py", line 372, in transpile
    circuits = parallel.parallel_map(
  File "/veracruz/home/d/dgoncalves/.local/lib/python3.8/site-packages/qiskit/tools/parallel.py", line 187, in parallel_map
    raise error
  File "/veracruz/home/d/dgoncalves/.local/lib/python3.8/site-packages/qiskit/tools/parallel.py", line 177, in parallel_map
    results = list(future)
  File "/apps/software/Anaconda/2020.11/lib/python3.8/concurrent/futures/process.py", line 484, in _chain_from_iterable_of_lists
    for element in iterable:
  File "/apps/software/Anaconda/2020.11/lib/python3.8/concurrent/futures/_base.py", line 611, in result_iterator
    yield fs.pop().result()
  File "/apps/software/Anaconda/2020.11/lib/python3.8/concurrent/futures/_base.py", line 432, in result
    return self.__get_result()
  File "/apps/software/Anaconda/2020.11/lib/python3.8/concurrent/futures/_base.py", line 388, in __get_result
    raise self._exception
concurrent.futures.process.BrokenProcessPool: A process in the process pool was terminated abruptly while the future was running or pending.
Traceback (most recent call last):
  File "/veracruz/projects/c/cquant/Dirac-Quantum-Walk/QuantumWalk/main.py", line 38, in <module>
    exec_answers = execute_circuits(all_results,shots,simulator,num_threads)
  File "/veracruz/projects/c/cquant/Dirac-Quantum-Walk/QuantumWalk/execute_circuits.py", line 9, in execute_circuits
    circuits_list = transpile(circuits_list, sim_statevector)
  File "/veracruz/home/d/dgoncalves/.local/lib/python3.8/site-packages/qiskit/compiler/transpiler.py", line 372, in transpile
    circuits = parallel.parallel_map(
  File "/veracruz/home/d/dgoncalves/.local/lib/python3.8/site-packages/qiskit/tools/parallel.py", line 187, in parallel_map
    raise error
  File "/veracruz/home/d/dgoncalves/.local/lib/python3.8/site-packages/qiskit/tools/parallel.py", line 177, in parallel_map
    results = list(future)
  File "/apps/software/Anaconda/2020.11/lib/python3.8/concurrent/futures/process.py", line 484, in _chain_from_iterable_of_lists
    for element in iterable:
  File "/apps/software/Anaconda/2020.11/lib/python3.8/concurrent/futures/_base.py", line 611, in result_iterator
    yield fs.pop().result()
  File "/apps/software/Anaconda/2020.11/lib/python3.8/concurrent/futures/_base.py", line 432, in result
    return self.__get_result()
  File "/apps/software/Anaconda/2020.11/lib/python3.8/concurrent/futures/_base.py", line 388, in __get_result
    raise self._exception
concurrent.futures.process.BrokenProcessPool: A process in the process pool was terminated abruptly while the future was running or pending.
srun: error: nau005: task 2: Exited with exit code 1
srun: error: nau005: task 0: Exited with exit code 1
